<?xml version="1.0" ?>
<sdf version='1.7'>
  <model name='scout_mini'>
    <!-- Base link -->
    <link name='base_link'> 
      <inertial>
        <mass>60</mass>
        <inertia>
          <ixx>2.28864</ixx>
          <ixy>0</ixy>
          <ixz>0</ixz>
          <iyy>5.10398</iyy>
          <iyz>0</iyz>
          <izz>3.43147</izz>
        </inertia>
      </inertial>
      
      <collision name='base_link_collision'>
        <pose>0 0 0 1.57 0 -1.57</pose>
        <geometry>
          <mesh>
            <scale>1 1 1</scale>
            <uri>model://scout_common/meshes/scout_mini_base_link2.dae</uri>
          </mesh>
        </geometry>
      </collision>
      
      <visual name='base_link_visual'>
        <pose>0 0 0 1.57 0 -1.57</pose>
        <geometry>
          <mesh>
            <scale>1 1 1</scale>
            <uri>model://scout_common/meshes/scout_mini_base_link2.dae</uri>
          </mesh>
        </geometry>
      </visual>
    </link>
 
    <!-- Scout wheels -->
    <link name='rear_left_wheel_link'>
      <pose relative_to='rear_left_wheel'>0 0 0 0 0 0</pose>
      
      <inertial>
        <mass>3</mass>
        <inertia>
          <ixx>0.7171</ixx>
          <ixy>0</ixy>
          <ixz>0</ixz>
          <iyy>0.7171</iyy>
          <iyz>0</iyz>
          <izz>0.1361</izz>
        </inertia>
      </inertial>
      
      <collision name='rear_left_wheel_link_collision'>
        <geometry>
          <mesh>
            <scale>1 1 1</scale>
            <uri>model://scout_common/meshes/wheel.dae</uri>
          </mesh>
        </geometry>
       <surface>
          <!-- This friction pamareter don't contain reliable data!! -->
           <friction>
            <ode>
              <mu>1</mu>
              <mu2>1</mu2>
              <fdir1>0 0 0</fdir1>
              <slip1>0.0</slip1>
              <slip2>0.0</slip2>
            </ode>
          </friction>
          <contact>
            <ode>
              <soft_cfm>0</soft_cfm>
              <soft_erp>0.2</soft_erp>
              <kp>1e+6</kp>
              <kd>1</kd>
              <max_vel>0.01</max_vel>
              <min_depth>0.001</min_depth>
            </ode>
          </contact>
        </surface> 
      </collision>
      
      <visual name='rear_left_wheel_link_visual'>
        <geometry>
          <mesh>
            <scale>1 1 1</scale>
            <uri>model://scout_common/meshes/wheel.dae</uri>
          </mesh>
        </geometry>
      </visual>
    </link>
    
    <joint name='rear_left_wheel' type='revolute'>
      <pose relative_to='base_link'>-0.231976 0.208252 -0.099998 -1.57 0 0</pose>
      
      <parent>base_link</parent>
      <child>rear_left_wheel_link</child>
      <axis>
        <xyz>0 0 1</xyz>
      </axis>
    </joint>
    
    <link name='rear_right_wheel_link'>
      <pose relative_to='rear_right_wheel'>0 0 0 0 0 0</pose>
      
      <inertial>
        <mass>3</mass>
        <inertia>
          <ixx>0.7171</ixx>
          <ixy>0</ixy>
          <ixz>0</ixz>
          <iyy>0.7171</iyy>
          <iyz>0</iyz>
          <izz>0.1361</izz>
        </inertia>
      </inertial>
      
      <collision name='rear_right_wheel_link_collision'>
        <geometry>
          <mesh>
            <scale>1 1 1</scale>
            <uri>model://scout_common/meshes/wheel.dae</uri>
          </mesh>
        </geometry>
        <surface>
          <!-- This friction pamareter don't contain reliable data!! -->
          <friction>
            <ode>
              <mu>1</mu>
              <mu2>1</mu2>
              <fdir1>0 0 0</fdir1>
              <slip1>0.0</slip1>
              <slip2>0.0</slip2>
            </ode>
          </friction>
          <contact>
            <ode>
              <soft_cfm>0</soft_cfm>
              <soft_erp>0.2</soft_erp>
              <kp>1e+6</kp>
              <kd>1</kd>
              <max_vel>0.01</max_vel>
              <min_depth>0.001</min_depth>
            </ode>
          </contact>
        </surface>
      </collision>
      
      <visual name='rear_right_wheel_link_visual'>
         <geometry>
          <mesh>
            <scale>1 1 1</scale>
            <uri>model://scout_common/meshes/wheel.dae</uri>
          </mesh>
        </geometry>
      </visual>
    </link>
    
    <joint name='rear_right_wheel' type='revolute'>
      <pose relative_to='base_link'>-0.231976 -0.208252 -0.100998 1.57 0 0</pose>
      
      <parent>base_link</parent>
      <child>rear_right_wheel_link</child>
      <axis>
        <xyz>0 0 -1</xyz>
      </axis>
    </joint>
    
    <link name='front_right_wheel_link'>
      <pose relative_to='front_right_wheel'>0 0 0 0 0 0</pose>
      
      <inertial>
        <mass>3</mass>
        <inertia>
          <ixx>0.7171</ixx>
          <ixy>0</ixy>
          <ixz>0</ixz>
          <iyy>0.7171</iyy>
          <iyz>0</iyz>
          <izz>0.1361</izz>
        </inertia>
      </inertial>
      
      <collision name='front_right_wheel_link_collision'>
        <geometry>
          <mesh>
            <scale>1 1 1</scale>
            <uri>model://scout_common/meshes/wheel.dae</uri>
          </mesh>
        </geometry>
        <surface>
          <!-- This friction pamareter don't contain reliable data!! -->
          <friction>
            <ode>
              <mu>1</mu>
              <mu2>1</mu2>
              <fdir1>0 0 0</fdir1>
              <slip1>0.0</slip1>
              <slip2>0.0</slip2>
            </ode>
          </friction>
          <contact>
            <ode>
              <soft_cfm>0</soft_cfm>
              <soft_erp>0.2</soft_erp>
              <kp>1e+6</kp>
              <kd>1</kd>
              <max_vel>0.01</max_vel>
              <min_depth>0.001</min_depth>
            </ode>
          </contact>
        </surface>
      </collision>
      
      <visual name='front_right_wheel_link_visual'>
        <geometry>
          <mesh>
            <scale>1 1 1</scale>
            <uri>model://scout_common/meshes/wheel.dae</uri>
          </mesh>
        </geometry>
      </visual>
    </link>
    
    <joint name='front_right_wheel' type='revolute'>
      <pose relative_to='base_link'>0.231976 -0.208252 -0.100998 1.57 0 0</pose>
      
      <parent>base_link</parent>
      <child>front_right_wheel_link</child>
      <axis>
        <xyz>0 0 -1</xyz>
      </axis>
    </joint>
    
    <link name='front_left_wheel_link'>
      <pose relative_to='front_left_wheel'>0 0 0 0 0 0</pose>
      
      <inertial>
        <mass>3</mass>
        <inertia>
          <ixx>0.7171</ixx>
          <ixy>0</ixy>
          <ixz>0</ixz>
          <iyy>0.7171</iyy>
          <iyz>0</iyz>
          <izz>0.1361</izz>
        </inertia>
      </inertial>
      
      <collision name='front_left_wheel_link_collision'>
        <geometry>
          <mesh>
            <scale>1 1 1</scale>
            <uri>model://scout_common/meshes/wheel.dae</uri>
          </mesh>
        </geometry>
        <surface>
          <!-- This friction pamareter don't contain reliable data!! -->
          <friction>
            <ode>
              <mu>1</mu>
              <mu2>1</mu2>
              <fdir1>0 0 0</fdir1>
              <slip1>0.0</slip1>
              <slip2>0.0</slip2>
            </ode>
          </friction>
          <contact>
            <ode>
              <soft_cfm>0</soft_cfm>
              <soft_erp>0.2</soft_erp>
              <kp>1e+6</kp>
              <kd>1</kd>
              <max_vel>0.01</max_vel>
              <min_depth>0.001</min_depth>
            </ode>
          </contact>
        </surface>
      </collision>
      
      <visual name='front_left_wheel_link_visual'>
        <geometry>
          <mesh>
            <scale>1 1 1</scale>
            <uri>model://scout_common/meshes/wheel.dae</uri>
          </mesh>
        </geometry>
      </visual>
    </link>

    <joint name='front_left_wheel' type='revolute'>
      <pose relative_to='base_link'>0.231976 0.208252 -0.099998 -1.57 0 0</pose>

      <parent>base_link</parent>
      <child>front_left_wheel_link</child>
      <axis>
        <xyz>0 0 1</xyz>
      </axis>
    </joint>
    
    <!-- Scout plugins -->
    <plugin name='scout_mini_joint_state' filename='libgazebo_ros_joint_state_publisher.so'>
      <ros>
        <namespace>/robot_namespace</namespace>
        <remapping>~/out:=joint_states</remapping>
      </ros>
      
      <update_rate>50</update_rate>
      
      <joint_name>front_right_wheel</joint_name>
      <joint_name>front_left_wheel</joint_name>
      <joint_name>rear_right_wheel</joint_name>
      <joint_name>rear_left_wheel</joint_name>
    </plugin>      

    <plugin name='skid_steer_drive' filename='libgazebo_ros_diff_drive.so'>
      <!-- topics & remappings -->
      <ros>
        <namespace>/robot_namespace</namespace>
        <remapping>/tf:=tf</remapping>
      </ros>
      <!-- Update rate -->
      <update_rate>50</update_rate>

      <!-- Number of wheel pairs -->
      <num_wheel_pairs>2</num_wheel_pairs>
        
      <!-- front wheels -->
      <left_joint>front_left_wheel</left_joint>
      <right_joint>front_right_wheel</right_joint>

      <!-- rear wheels-->
      <left_joint>rear_left_wheel</left_joint>
      <right_joint>rear_right_wheel</right_joint>

      <!-- kinematics -->
      <wheel_separation>0.490</wheel_separation>
      <wheel_separation>0.490</wheel_separation>
      <wheel_diameter>0.160</wheel_diameter>
      <wheel_diameter>0.160</wheel_diameter>
              
      <!-- limits -->
      <max_wheel_torque>20</max_wheel_torque>
      <max_wheel_acceleration>1.0</max_wheel_acceleration>

      <!-- output -->
      <publish_odom>true</publish_odom>
      <publish_odom_tf>true</publish_odom_tf> <!-- set to false if we use navigation, true if we use slam, true also if we don't use localization nodes in nav2 stack -->
      <publish_wheel_tf>false</publish_wheel_tf>

      <odometry_frame>odom</odometry_frame>
      <odometry_topic>odom</odometry_topic>
      <robot_base_frame>base_link</robot_base_frame>
    </plugin>

    <!-- Scout sensors -->
    <!-- IMU -->
    <link name="imu_link">
      <pose>0 0 0.06 0 0 0</pose>
      <inertial>
        <inertia>
          <ixx>0.000024167</ixx>
          <ixy>0.000</ixy>
          <ixz>0.000</ixz>
          <iyy>0.000024167</iyy>
          <iyz>0.000</iyz>
          <izz>0.000041667</izz>
        </inertia>
        <mass>0.1</mass>
      </inertial>

      <collision name="imu_sensor_collision">
        <geometry>
          <box>
            <size>0.05 0.05 0.02</size>
          </box>
        </geometry>
      </collision>

      <visual name="imu_sensor_visual">
        <geometry>
          <box>
            <size>0.05 0.05 0.02</size>
          </box>
        </geometry>
        <color rgba="0.3 0.3 0.3 1.0"/>
      </visual>

      <sensor name="imu_sensor" type="imu">
        <always_on>true</always_on>
        <update_rate>100</update_rate>
        <orientation_reference_frame>
          <localization>"ENU"</localization>
        </orientation_reference_frame>
        
        <plugin name="imu_plugin" filename="libgazebo_ros_imu_sensor.so">
          <ros>
            <namespace>/robot_namespace</namespace>
            <remapping>~/out:=imu</remapping>
          </ros>
          <initial_orientation_as_reference>false</initial_orientation_as_reference>
        </plugin>
      </sensor>
    </link>
    
    <joint name="imu_joint" type="fixed">
      <parent>base_link</parent>
      <child>imu_link</child>
      <pose>0 0 0 0 0 0</pose>
    </joint>

    <!-- RPLIDAR A3 -->
    <link name="base_scan">
      <pose>0.15 0 0.1 0 0 0</pose>
      <inertial>
        <inertia>
          <ixx>0.001</ixx>
          <ixy>0.000</ixy>
          <ixz>0.000</ixz>
          <iyy>0.001</iyy>
          <iyz>0.000</iyz>
          <izz>0.001</izz>
        </inertia>
        <mass>0.2</mass>
      </inertial>

      <collision name="lidar_sensor_collision">
        <geometry>
          <cylinder>
            <radius>0.038</radius>
            <length>0.041</length>
          </cylinder>
        </geometry>
      </collision>

      <visual name="lidar_sensor_visual">
        <geometry>
          <cylinder>
            <radius>0.038</radius>
            <length>0.041</length>
          </cylinder>
        </geometry>
        <color rgba="0.3 0.3 0.3 1.0"/>
      </visual>

      <sensor name="rplidar_a3" type="ray">
        <always_on>true</always_on>
        <visualize>false</visualize>
        <update_rate>10</update_rate>
        
        <ray>
          <scan>
            <horizontal>
                <samples>1875</samples>
                <resolution>1</resolution>
                <min_angle>-3.14159</min_angle>
                <max_angle>3.14159</max_angle>
            </horizontal>
            <vertical>
                <samples>16</samples>
                <resolution>1</resolution>
                <min_angle>-0.261799</min_angle>
                <max_angle>0.261799</max_angle>
            </vertical>
          </scan>
          <range>
            <min>0.2</min>
            <max>4.0</max>
            <resolution>0.001</resolution>
          </range>
          <noise>
            <type>gaussian</type>
            <mean>0.0</mean>
            <stddev>0.01</stddev>
          </noise>
        </ray>
        
        <plugin name='gazebo_ros_laser_controller' filename='libgazebo_ros_velodyne_laser.so'>
            <frameName>/velodyne</frameName>
            <min_range>0.5</min_range>
            <max_range>120.0</max_range>
            <gaussianNoise>0.008</gaussianNoise>
            <ros>
              <namespace>/robot_namespace</namespace>
              <remapping>~/out:=points2</remapping>
            </ros>
          </plugin>
      </sensor>
    </link> 
    
     <joint name="lidar_joint" type="fixed">
      <parent>base_link</parent>
      <child>base_scan</child>
      <pose>0 0 0 0 0 0</pose>
    </joint>

    <!-- Depth Camera -->
    <link name='camera_link'>
      <inertial>
        <pose>0.25 0.0 0.05 0 -0 0</pose>
        <mass>0.072</mass>
        <inertia>
          <ixx>0.00388124</ixx>
          <ixy>0</ixy>
          <ixz>0</ixz>
          <iyy>0.00049894</iyy>
          <iyz>0</iyz>
          <izz>0.00387926</izz>
        </inertia>
      </inertial>
      <collision name='camera_link_fixed_joint_lump__camera_link_collision'>
        <pose>0.25 0.0 0.05 0 -0 0</pose>
        <geometry>
          <box>
            <size>0.02505 0.09 0.025</size>
          </box>
        </geometry>
        <surface>
          <contact>
            <ode>
              <kp>1e+13</kp>
              <kd>1</kd>
            </ode>
          </contact>
          <friction>
            <ode>
              <mu2>1</mu2>
              <fdir1>0 0 0</fdir1>
            </ode>
          </friction>
        </surface>
      </collision>
      <visual name='camera_link_fixed_joint_lump__camera_link_visual'>
        <pose>0.25 0.0 0.05 1.5708 -0 1.5708</pose>
        <geometry>
          <mesh>
            <scale>1 1 1</scale>
            <uri>model://scout_common/meshes/d435.dae</uri>
          </mesh>
        </geometry>
      </visual>
      <self_collide>0</self_collide>
      <enable_wind>0</enable_wind>
      <kinematic>0</kinematic>
      <gravity>1</gravity>
      <sensor name='cameracolor' type='camera'>
        <camera name='camera'>
          <horizontal_fov>1.21126</horizontal_fov>
          <image>
            <width>640</width>
            <height>480</height>
            <format>RGB_INT8</format>
          </image>
          <clip>
            <near>0.1</near>
            <far>100</far>
          </clip>
          <noise>
            <type>gaussian</type>
            <mean>0</mean>
            <stddev>0.007</stddev>
          </noise>
        </camera>
        <always_on>1</always_on>
        <update_rate>30</update_rate>
        <visualize>1</visualize>
        <pose>0.25 0.0 0.05 0 -0 0</pose>
      </sensor>
      <sensor name='cameraired1' type='camera'>
        <camera name='camera'>
          <horizontal_fov>1.48702</horizontal_fov>
          <image>
            <width>1280</width>
            <height>720</height>
            <format>L_INT8</format>
          </image>
          <clip>
            <near>0.1</near>
            <far>100</far>
          </clip>
          <noise>
            <type>gaussian</type>
            <mean>0</mean>
            <stddev>0.05</stddev>
          </noise>
        </camera>
        <always_on>1</always_on>
        <update_rate>90</update_rate>
        <visualize>0</visualize>
        <pose>0.25 0.0 0.05 0 -0 0</pose>
      </sensor>
      <sensor name='cameraired2' type='camera'>
        <camera name='camera'>
          <horizontal_fov>1.48702</horizontal_fov>
          <image>
            <width>1280</width>
            <height>720</height>
            <format>L_INT8</format>
          </image>
          <clip>
            <near>0.1</near>
            <far>100</far>
          </clip>
          <noise>
            <type>gaussian</type>
            <mean>0</mean>
            <stddev>0.05</stddev>
          </noise>
        </camera>
        <always_on>1</always_on>
        <update_rate>90</update_rate>
        <visualize>0</visualize>
        <pose>0.25 0.0 0.05 0 -0 0</pose>
      </sensor>
      <sensor name='cameradepth' type='depth'>
        <camera name='camera'>
          <horizontal_fov>1.48702</horizontal_fov>
          <image>
            <width>1280</width>
            <height>720</height>
          </image>
          <clip>
            <near>0.1</near>
            <far>100</far>
          </clip>
          <noise>
            <type>gaussian</type>
            <mean>0</mean>
            <stddev>0.1</stddev>
          </noise>
        </camera>
        <always_on>1</always_on>
        <update_rate>90</update_rate>
        <visualize>0</visualize>
        <pose>0.25 0.0 0.05 0 -0 0</pose>
      </sensor>
    </link>
    <static>0</static>
    
    <plugin name='intel_d435_camera' filename='librealsense_gazebo_plugin.so'>
      <prefix>camera</prefix>
      <depthUpdateRate>30.0</depthUpdateRate>
      <colorUpdateRate>30.0</colorUpdateRate>
      <infraredUpdateRate>30.0</infraredUpdateRate>
      <depthTopicName>depth/image_raw</depthTopicName>
      <depthCameraInfoTopicName>depth/camera_info</depthCameraInfoTopicName>
      <colorTopicName>color/image_raw</colorTopicName>
      <colorCameraInfoTopicName>color/camera_info</colorCameraInfoTopicName>
      <infrared1TopicName>infra1/image_raw</infrared1TopicName>
      <infrared1CameraInfoTopicName>infra1/camera_info</infrared1CameraInfoTopicName>
      <infrared2TopicName>infra2/image_raw</infrared2TopicName>
      <infrared2CameraInfoTopicName>infra2/camera_info</infrared2CameraInfoTopicName>
      <colorOpticalframeName>camera_color_optical_frame</colorOpticalframeName>
      <depthOpticalframeName>camera_depth_optical_frame</depthOpticalframeName>
      <infrared1OpticalframeName>camera_left_ir_optical_frame</infrared1OpticalframeName>
      <infrared2OpticalframeName>camera_right_ir_optical_frame</infrared2OpticalframeName>
      <rangeMinDepth>0.2</rangeMinDepth>
      <rangeMaxDepth>4.0</rangeMaxDepth>
      <pointCloud>1</pointCloud>
      <pointCloudTopicName>depth/color/points</pointCloudTopicName>
      <pointCloudCutoff>0.25</pointCloudCutoff>
      <pointCloudCutoffMax>4.0</pointCloudCutoffMax>
    </plugin>
    
    <joint name="camera_joint" type="fixed">
      <parent>base_link</parent>
      <child>camera_link</child>
      <pose>0 0 0 0 0 0</pose>
    </joint>
    
    <!-- GPS -->
    <!--
    <link name="gps_link">
      <pose>-0.10 -0.125 0.3 0 0 0</pose>
      <inertial>
        <inertia>
          <ixx>0.001</ixx>
          <ixy>0.000</ixy>
          <ixz>0.000</ixz>
          <iyy>0.001</iyy>
          <iyz>0.000</iyz>
          <izz>0.001</izz>
        </inertia>
        <mass>0.2</mass>
      </inertial>

      <collision name="gps_antenna_collision">
        <geometry>
          <cylinder>
            <radius>0.04</radius>
            <length>0.02</length>
          </cylinder>
        </geometry>
      </collision>

      <visual name="gps_antenna_visual">
        <geometry>
          <cylinder>
            <radius>0.04</radius>
            <length>0.02</length>
          </cylinder>
        </geometry>
        <color rgba="0.3 0.3 0.3 1.0"/>
      </visual>

      <collision name="gps_pole_visual">
        <pose>0 0 -0.155 0 0 0</pose>
        <geometry>
          <cylinder>
            <radius>0.005</radius>
            <length>0.3</length>
          </cylinder>
        </geometry>
      </collision>

      <visual name="gps_pole_visual">
        <pose>0 0 -0.155 0 0 0</pose>
        <geometry>
          <cylinder>
            <radius>0.005</radius>
            <length>0.3</length>
          </cylinder>
        </geometry>
        <color rgba="0.3 0.3 0.3 1.0"/>
      </visual>

      <sensor name="gps_sensor" type="gps">
        <always_on>true</always_on>
        <update_rate>1.0</update_rate>
        
        <plugin name="gps_controller" filename="libgazebo_ros_gps_sensor.so">
            <ros>
                <namespace>/robot_namespace</namespace>
                <remapping>gps_controller/out:=fix</remapping> <!- - Previously was on :=gps - ->
                <remapping>gps_controller/vel:=fix/vel</remapping> <!- - Previously was on :=gps/vel - ->
            </ros>
            <frame_name>gps_link</frame_name>
        </plugin>
      </sensor>
    </link>

    <joint name="gps_joint" type="fixed">
      <parent>base_link</parent>
      <child>gps_link</child>
      <pose>0 0 0 0 0 0</pose>
    </joint>
    -->
  </model>
</sdf>
