<?xml version="1.0" ?>
<sdf version='1.7'>
  <model name='scout_v2'>
  
    <!-- Just for testing
    <joint name='world_to_base_link' type='fixed'>
      <pose relative_to='__model__'>0 0 0.5 0 0 0</pose>
      <parent>world</parent>
      <child>base_link</child>
    </joint> -->

    <link name='base_link'>
      <!-- <pose relative_to='world_to_base_link'>0 0 0 0 0 0</pose> -->

      <inertial>
        <pose>0 0 0 0 0 0</pose>
        <mass>50</mass>
        <inertia>
          <ixx>2.28864</ixx>
          <ixy>0</ixy>
          <ixz>0</ixz>
          <iyy>5.10398</iyy>
          <iyz>0</iyz>
          <izz>3.43147</izz>
        </inertia>
      </inertial>
      
      <collision name='base_link_collision'>
        <pose>0 0 0.008 0 0 0</pose>
        <geometry>
          <box>
            <size>0.925 0.38 0.21</size>
          </box>
        </geometry>
      </collision>
      
      <collision name='base_link_collision_1'>
        <pose>0 0 0.035 0 0 0</pose>
        <geometry>
          <box>
            <size>0.154167 0.627 0.07</size>
          </box>
        </geometry>
      </collision>
      
      <visual name='base_link_visual'>
        <pose>0 0 0 0 0 0</pose>
        <geometry>
         <mesh>
            <scale>1 1 1</scale>
            <uri>model://scout_common/meshes/base_link.dae</uri>
          </mesh>
        </geometry>
      </visual>
    </link>
    
    <joint name='front_left_wheel' type='revolute'>
      <pose relative_to='base_link'>0.249 0.29153 -0.0702 0 0 0</pose>
      <parent>base_link</parent>
      <child>front_left_wheel_link</child>
      <axis>
        <xyz>0 1 0</xyz>
      </axis>
    </joint>
    
    <link name='front_left_wheel_link'>
      <pose relative_to='front_left_wheel'>0 0 0 0 0 0</pose>
      
      <inertial>
        <pose>0 0 0 0 -0 0</pose>
        <mass>8</mass>
        <inertia>
          <ixx>0.1171</ixx>
          <ixy>0</ixy>
          <ixz>0</ixz>
          <iyy>0.1361</iyy>
          <iyz>0</iyz>
          <izz>0.1171</izz>
        </inertia>
      </inertial>
      
      <collision name='front_left_wheel_link_collision'>
        <pose>0 0 0 1.57079 -0 0</pose>
        <geometry>
          <cylinder>
            <length>0.11653</length>
            <radius>0.16459</radius>
          </cylinder>
        </geometry>
        <surface>
          <contact>
            <ode>
              <kp>1e+09</kp>
              <kd>0</kd>
              <min_depth>0.001</min_depth>
            </ode>
          </contact>
          <friction>
            <ode>
              <mu>0.9</mu>
              <mu2>0.7</mu2>
              <fdir1>1 0 0</fdir1>
            </ode>
          </friction>
        </surface>
      </collision>
      
      <visual name='front_left_wheel_link_visual'>
        <pose>0 0 0 0 0 0</pose>
        <geometry>
          <mesh>
            <scale>1 1 1</scale>
            <uri>model://scout_common/meshes/wheel_type1.dae</uri>
          </mesh>
        </geometry>
      </visual>
    </link>
    
    <joint name='front_right_wheel' type='revolute'>
      <pose relative_to='base_link'>0.249 -0.29153 -0.0702 3.14 0 0</pose>
      <parent>base_link</parent>
      <child>front_right_wheel_link</child>
      <axis>
        <xyz>0 -1 0</xyz>
      </axis>
    </joint>
    
    <link name='front_right_wheel_link'>
      <pose relative_to='front_right_wheel'>0 0 0 0 0 0</pose>
      
      <inertial>
        <pose>0 0 0 0 -0 0</pose>
        <mass>8</mass>
        <inertia>
          <ixx>0.1171</ixx>
          <ixy>0</ixy>
          <ixz>0</ixz>
          <iyy>0.1361</iyy>
          <iyz>0</iyz>
          <izz>0.1171</izz>
        </inertia>
      </inertial>
      
      <collision name='front_right_wheel_link_collision'>
        <pose>0 0 0 1.57079 -0 0</pose>
        <geometry>
          <cylinder>
            <length>0.11653</length>
            <radius>0.16459</radius>
          </cylinder>
        </geometry>
        <surface>
          <contact>
            <ode>
              <kp>1e+09</kp>
              <kd>0</kd>
              <min_depth>0.001</min_depth>
            </ode>
          </contact>
          <friction>
            <ode>
              <mu>0.9</mu>
              <mu2>0.7</mu2>
              <fdir1>1 0 0</fdir1>
            </ode>
          </friction>
        </surface>
      </collision>
      
      <visual name='front_right_wheel_link_visual'>
        <pose>0 0 0 0 0 0</pose>
        <geometry>
          <mesh>
            <scale>1 1 1</scale>
            <uri>model://scout_common/meshes/wheel_type1.dae</uri>
          </mesh>
        </geometry>
      </visual>
    </link>
    
    <joint name='rear_left_wheel' type='revolute'>
      <pose relative_to='base_link'>-0.249 0.29153 -0.0702 0 0 0</pose>
      
      <parent>base_link</parent>
      <child>rear_left_wheel_link</child>
      <axis>
        <xyz>0 1 0</xyz>
      </axis>
    </joint>
    
    <link name='rear_left_wheel_link'>
      <pose relative_to='rear_left_wheel'>0 0 0 0 0 0</pose>
      
      <inertial>
        <pose>0 0 0 0 -0 0</pose>
        <mass>8</mass>
        <inertia>
          <ixx>0.1171</ixx>
          <ixy>0</ixy>
          <ixz>0</ixz>
          <iyy>0.1361</iyy>
          <iyz>0</iyz>
          <izz>0.1171</izz>
        </inertia>
      </inertial>
      
      <collision name='rear_left_wheel_link_collision'>
        <pose>0 0 0 1.57079 0 0</pose>
        <geometry>
          <cylinder>
            <length>0.11653</length>
            <radius>0.16459</radius>
          </cylinder>
        </geometry>
        <surface>
          <contact>
            <ode>
              <kp>1e+09</kp>
              <kd>0</kd>
              <min_depth>0.001</min_depth>
            </ode>
          </contact>
          <friction>
            <ode>
              <mu>0.9</mu>
              <mu2>0.7</mu2>
              <fdir1>1 0 0</fdir1>
            </ode>
          </friction>
        </surface>
      </collision>
      
      <visual name='rear_left_wheel_link_visual'>
        <pose>0 0 0 0 -0 0</pose>
        <geometry>
          <mesh>
            <scale>1 1 1</scale>
            <uri>model://scout_common/meshes/wheel_type1.dae</uri>
          </mesh>
        </geometry>
      </visual>
    </link>
    
    <joint name='rear_right_wheel' type='revolute'>
      <pose relative_to='base_link'>-0.249 -0.29153 -0.0702 3.14 0 0</pose>
      
      <parent>base_link</parent>
      <child>rear_right_wheel_link</child>
      <axis>
        <xyz>0 -1 0</xyz>
      </axis>
    </joint>
    
    <link name='rear_right_wheel_link'>
      <pose relative_to='rear_right_wheel'>0 0 0 0 0 0</pose>
      
      <inertial>
        <pose>0 0 0 0 0 0</pose>
        <mass>8</mass>
        <inertia>
          <ixx>0.1171</ixx>
          <ixy>0</ixy>
          <ixz>0</ixz>
          <iyy>0.1361</iyy>
          <iyz>0</iyz>
          <izz>0.1171</izz>
        </inertia>
      </inertial>
      
      <collision name='rear_right_wheel_link_collision'>
        <pose>0 0 0 1.57079 0 0</pose>
        <geometry>
          <cylinder>
            <length>0.11653</length>
            <radius>0.16459</radius>
          </cylinder>
        </geometry>
        <surface>
          <contact>
            <ode>
              <kp>1e+09</kp>
              <kd>0</kd>
              <min_depth>0.001</min_depth>
            </ode>
          </contact>
          <friction>
            <ode>
              <mu>0.9</mu>
              <mu2>0.7</mu2>
              <fdir1>1 0 0</fdir1>
            </ode>
          </friction>
        </surface>
      </collision>
      
      <visual name='rear_right_wheel_link_visual'>
        <pose>0 0 0 0 0 0</pose>
        <geometry>
          <mesh>
            <scale>1 1 1</scale>
            <uri>model://scout_common/meshes/wheel_type1.dae</uri>
          </mesh>
        </geometry>
      </visual>
    </link>

    <plugin name="scout_v2_joint_state" filename="libgazebo_ros_joint_state_publisher.so">
      <ros>
        <namespace>/robot_namespace</namespace>
        <remapping>~/out:=joint_states</remapping>
      </ros>
      
      <update_rate>50</update_rate>
      
      <joint_name>front_right_wheel</joint_name>
      <joint_name>front_left_wheel</joint_name>
      <joint_name>rear_right_wheel</joint_name>
      <joint_name>rear_left_wheel</joint_name>
    </plugin>      

    <plugin name='skid_steer_drive' filename='libgazebo_ros_diff_drive.so'>
      <!-- topics & remappings -->
      <ros>
        <namespace>/robot_namespace</namespace>
        <remapping>/tf:=tf</remapping>
      </ros>
        
      <!-- Update rate -->
      <update_rate>50</update_rate>

      <!-- Number of wheel pairs -->
      <num_wheel_pairs>2</num_wheel_pairs>
        
      <!-- front wheels -->
      <left_joint>front_left_wheel</left_joint>
      <right_joint>front_right_wheel</right_joint>

      <!-- rear wheels-->
      <left_joint>rear_left_wheel</left_joint>
      <right_joint>rear_right_wheel</right_joint>

      <!-- kinematics -->
      <wheel_separation>0.582</wheel_separation>
      <wheel_separation>0.582</wheel_separation>
      <wheel_diameter>0.32918</wheel_diameter>
      <wheel_diameter>0.32918</wheel_diameter>
              
      <wheel_separation_multiplier>1.875</wheel_separation_multiplier>
      <left_wheel_radius_multiplier>1.0</left_wheel_radius_multiplier>
      <right_wheel_radius_multiplier>1.0</right_wheel_radius_multiplier>

      <!-- limits -->
      <max_wheel_torque>20</max_wheel_torque>
      <max_wheel_acceleration>1.0</max_wheel_acceleration>

      <!-- output -->
      <publish_odom>true</publish_odom>
      <publish_odom_tf>false</publish_odom_tf>
      <publish_wheel_tf>false</publish_wheel_tf>

      <odometry_frame>odom</odometry_frame>
      <robot_base_frame>base_link</robot_base_frame>       
    </plugin>
  </model>
</sdf>
